Workbook

Sheet GralJulio
A1: s | C1: TIPO DE GESTIÓN | E1: CERRADAS | H1: LICITANDO | K1: COORDINADAS | N1: PENDIENTES | V1: VALORES ACTUALES | W1: PERICIA | X1: CARGA | Z1: (Modificar los valores de V14 y X14 para que se automatice el precio)
V2: IP CON ORDEN | W2: 5625 | X2: 5250 | Z2: PERITO - KILOMETRAJE | AB2: HONORARIOS | AC2: AOM
C4: IP CON ORDEN | E4: =COUNTIFS(General!F:F, "IP CERRADA", General!H:H, "PTE. APROBACION", General!G:G, "IP CON ORDEN", General!O:O, ">="&DATE(2025,7,1), General!O:O, "<="&DATE(2025,7,31)) -> 142 | G4: =COUNTIFS(General!F:F, "IP CERRADA", General!M:M, "A MIÑO", General!H:H, "PTE. APROBACION", General!G:G, "IP CON ORDEN", General!O:O, ">="&DATE(2025,7,1), General!O:O, "<="&DATE(2025,7,31)) -> 0 | H4: =COUNTIFS(General!F:F, "LICITANDO REPUESTOS", General!G:G, "IP CON ORDEN") -> 15 | K4: =COUNTIFS(General!F:F, "IP COORDINADA", General!G:G, "IP CON ORDEN") -> 32 | N4: SIN CONTACTAR | O4: =COUNTIFS(General!F:F, "PENDIENTE COORDINACION") -> 5 | V4: POSIBLE DT | W4: 5625 | X4: 5250 | Z4: Lucas Del Piero | AA4: =#REF! -> #REF! | AB4: =AA4*$R$14 -> #REF! | AC4: =AB4*$T$14 -> #REF!
C5: POSIBLE DT | E5: =COUNTIFS(General!F:F, "IP CERRADA", General!H:H, "PTE. APROBACION", General!G:G, "POSIBLE DT", General!O:O, ">="&DATE(2025,7,1), General!O:O, "<="&DATE(2025,7,31)) -> 12 | H5: =COUNTIFS(General!F:F, "LICITANDO REPUESTOS", General!G:G, "POSIBLE DT") -> 0 | K5: =COUNTIFS(General!F:F, "IP COORDINADA", General!G:G, "POSIBLE DT") -> 2 | N5: CONTACTADOS | O5: =COUNTIFS(General!F:F, "CONTACTADO") -> 2 | V5: IP SIN ORDEN | W5: 5625 | X5: 5250 | Z5: Alfredo Miño | AA5: =#REF! -> #REF! | AB5: =AA5*$R$14 -> #REF! | AC5: =AB5*$T$14 -> #REF!
C6: IP SIN ORDEN | E6: =COUNTIFS(General!F:F, "IP CERRADA", General!H:H, "PTE. APROBACION", General!G:G, "IP SIN ORDEN", General!O:O, ">="&DATE(2025,7,1), General!O:O, "<="&DATE(2025,7,31)) -> 59 | H6: =COUNTIFS(General!F:F, "LICITANDO REPUESTOS", General!G:G, "IP SIN ORDEN") -> 0 | K6: =COUNTIFS(General!F:F, "IP COORDINADA", General!G:G, "IP SIN ORDEN") -> 0 | N6: EN NEGOCIACIÓN | O6: =COUNTIFS(General!F:F, "PENDIENTE DE OFRECIMIENTO") -> 0 | V6: AMPLIACION | W6: 2500 | X6: 2000 | Z6: Cristian Cribari | AA6: =#REF! -> #REF! | AB6: =AA6*$R$14 -> #REF! | AC6: =AB6*$T$14 -> #REF!
C7: AMPLIACION | E7: =COUNTIFS(General!F:F, "IP CERRADA", General!H:H, "PTE. APROBACION", General!G:G, "AMPLIACION", General!O:O, ">="&DATE(2025,7,1), General!O:O, "<="&DATE(2025,7,31)) -> 25 | H7: =COUNTIFS(General!F:F, "LICITANDO REPUESTOS", General!G:G, "AMPLIACION") -> 1 | K7: =COUNTIFS(General!F:F, "IP COORDINADA", General!G:G, "AMPLIACION") -> 0 | N7: MAILS SIN RESOLVER | O7: =COUNTIFS(General!F:F, "REVISAR MAIL - SIN RESOLVER") -> 0 | V7: ENVIO DE ORDEN | W7: 0 | X7: 0 | Z7: Ezequiel Chimento | AA7: =#REF! -> #REF! | AB7: =AA7*$R$14 -> #REF! | AC7: =AB7*$T$14 -> #REF!
C8: ENVIO DE ORDEN | E8: =COUNTIFS(General!F:F, "IP CERRADA", General!H:H, "PTE. APROBACION", General!G:G, "ENVIO DE ORDEN", General!O:O, ">="&DATE(2025,7,1), General!O:O, "<="&DATE(2025,7,31)) -> 0 | H8: =COUNTIFS(General!F:F, "LICITANDO REPUESTOS", General!G:G, "ENVIO DE ORDEN") -> 0 | K8: =COUNTIFS(General!F:F, "ENVIO DE ORDEN", General!G:G, "ENVIO DE ORDEN") -> 0 | V8: AUSENTE | W8: 1500 | X8: - | Z8: Ezequiel Dzyhajlo | AA8: =#REF! -> #REF! | AB8: =AA8*$R$14 -> #REF! | AC8: =AB8*$T$14 -> #REF!
C9: IP CAMIONES | E9: =COUNTIFS(General!F:F, "IP CERRADA", General!H:H, "PTE. APROBACION", General!G:G, "IP CAMIONES", General!O:O, ">="&DATE(2025,7,1), General!O:O, "<="&DATE(2025,7,31)) -> 0 | H9: =COUNTIFS(General!F:F, "LICITANDO REPUESTOS", General!G:G, "IP CAMIONES") -> 0 | K9: =COUNTIFS(General!F:F, "IP COORDINADA", General!G:G, "IP CAMIONES") -> 0 | N9: AUSENTE | O9: =COUNTIFS(General!F:F, "IP CERRADA", General!H:H, "PTE. APROBACION", General!G:G, "AUSENTE", General!O:O, ">="&DATE(2025,7,1), General!O:O, "<="&DATE(2025,7,31)) -> 14 | V9: TERCEROS | W9: 5625 | X9: 5625 | Z9: Franco Rodriguez | AA9: =#REF! -> #REF! | AB9: =AA9*$R$14 -> #REF! | AC9: =AB9*$T$14 -> #REF!
C10: TERCEROS | E10: =COUNTIFS(General!F:F, "IP CERRADA", General!H:H, "PTE. APROBACION", General!G:G, "TERCEROS", General!O:O, ">="&DATE(2024,3,1), General!O:O, ">="&DATE(2025,7,1), General!O:O, "<="&DATE(2025,7,31)) -> 2 | H10: =COUNTIFS(General!F:F, "LICITANDO REPUESTOS", General!G:G, "TERCEROS") -> 0 | K10: =COUNTIFS(General!F:F, "IP COORDINADA", General!G:G, "TERCEROS") -> 0 | V10: FOTOS | W10: 0 | X10: 0 | Z10: Gaston Di Clemente | AA10: =#REF! -> #REF! | AB10: =AA10*$R$14 -> #REF! | AC10: =AB10*$T$14 -> #REF!
C11: FOTOS | E11: =COUNTIFS(General!F:F, "IP CERRADA", General!H:H, "PTE. APROBACION", General!G:G, "FOTOS", General!O:O, ">="&DATE(2025,7,1), General!O:O, "<="&DATE(2025,7,31)) -> 0 | H11: =COUNTIFS(General!F:F, "LICITANDO REPUESTOS", General!G:G, "FOTOS") -> 0 | K11: =COUNTIFS(General!F:F, "IP COORDINADA", General!G:G, "FOTOS") -> 0 | V11: IP REMOTA | W11: 0 | X11: 0 | Z11: Rodrigo Arin | AA11: =#REF! -> #REF! | AB11: =AA11*$R$14 -> #REF! | AC11: =AB11*$T$14 -> #REF!
C12: IP REMOTA | E12: =COUNTIFS(General!F:F, "IP CERRADA", General!H:H, "PTE. APROBACION", General!G:G, "IP REMOTA", General!O:O, ">="&DATE(2025,7,1), General!O:O, "<="&DATE(2025,7,31)) -> 0 | H12: =COUNTIFS(General!F:F, "LICITANDO REPUESTOS", General!G:G, "IP REMOTA") -> 0 | K12: =COUNTIFS(General!F:F, "IP COORDINADA", General!G:G, "IP REMOTA") -> 0 | N12: KILOMETRAJE | V12: IP CAMIONES | W12: 5625 | X12: 5250
C13: IP VIRTUAL | E13: =COUNTIFS(General!F:F, "IP CERRADA", General!H:H, "PTE. APROBACION", General!G:G, "IP VIRTUAL", General!O:O, ">="&DATE(2025,7,1), General!O:O, "<="&DATE(2025,7,31)) -> 0 | H13: =COUNTIFS(General!F:F, "LICITANDO REPUESTOS", General!G:G, "IP VIRTUAL") -> 0 | K13: =COUNTIFS(General!F:F, "IP COORDINADA", General!G:G, "IP VIRTUAL") -> 0 | N13: =SUMIFS(General!P2:P2771, General!L2:L2771, ">=01/06/2024", General!L2:L2771, "<=31/06/2024") -> 0 | V13: IP VIRTUAL | W13: - | X13: -
E14: =E4+E5+E6+E7+E8+E9+E10+E11+E12+E13 -> 240 | F14: TOTALES | H14: =H4+H5+H6+H7+H8+H9+H10+H11+H12+H13 -> 16 | I14: TOTALES | K14: =K4+K5+K6+K7+K8+K9+K10+K11+K12+K13 -> 34 | L14: TOTALES | N14: =N13*T14 -> 0
E16: TOTAL CERRADO | H16: TOTAL LICITANDO | K16: TOTAL PENDIENTE | N16: EN TRAMITE | O16: =COUNTIFS(General!H:H, "EN TRAMITE") -> 98 | V16: KM RECORRIDO | W16: 300 | X16: - | Z16: TOTAL | AA16: =AA4+AA5+AA6+AA7+AA8+AA9+AA10+AA11 -> #REF! | AB16: =AB4+AB5+AB6+AB7+AB8+AB9+AB10+AB11 -> #REF! | AC16: =AC4+AC5+AC6+AC7+AC8+AC9+AC10+AC11 -> #REF!
E17: =E4+E5+E6+E7+E8+E9+E10+E12+O9+E13 -> 254 | H17: =H4+H5+H6+H7+H8+H9+H10+H11+H12+H13 -> 16 | K17: =K4+K5+K6+K7+K8+K9+K10+K11+K12+K13 -> 34 | N17: PTE. APROBACION | O17: =COUNTIFS(General!H:H, "PTE. APROBACION") -> 3403 | Q17: (Con kilometraje ya incluido)
N18: ANULADO | O18: =COUNTIFS(General!H:H, "ANULADO") -> 198 | Q18: PERITOS | S18: HONORARIOS | V18: IP CON ORDEN | W18: =COUNTIFS(General!F:F, "PARA FACTURAR", General!G:G, "IP CON ORDEN") -> 13
C19: DERIVACIONES TOTALES 2025 | E19: =E21+E22+E23+E24+E25+E26+E27+E28+E29+E30+E31+E32 -> 3248 | H19: TOTAL POTENCIAL | N19: PARA FACTURAR | O19: =COUNTIFS(General!F:F, "PARA FACTURAR") -> 22 | V19: POSIBLE DT | W19: =COUNTIFS(General!F:F, "PARA FACTURAR", General!G:G, "POSIBLE DT") -> 2
C20: PERICIAS DERIVADAS | E20: CANTIDAD | H20: =E17+H17+K17+O19 -> 326 | Q20: Rodrigo Arin | S20: =#REF! -> #REF! | V20: IP SIN ORDEN | W20: =COUNTIFS(General!F:F, "PARA FACTURAR", General!G:G, "IP SIN ORDEN") -> 6
C21: ENERO | E21: =COUNTIFS(General!B:B, ">="&DATE(2025,1,1), General!B:B, "<="&DATE(2025,1,31)) -> 260 | F21: =(E21-E36)/E36 -> #DIV/0! | Q21: Alfredo Miño | S21: =PeritosJulio!H21 -> 11250 | V21: AMPLIACION | W21: =COUNTIFS(General!F:F, "PARA FACTURAR", General!G:G, "AMPLIACION") -> 1
C22: FEBRERO | E22: =COUNTIFS(General!B:B, ">="&DATE(2025,2,1), General!B:B, "<="&DATE(2025,2,31)) -> 194 | F22: =(E22-E37)/E37 -> #DIV/0! | Q22: Cristian Cribari | S22: =PeritosJulio!W44 -> 0 | V22: ENVIO DE ORDEN | W22: =COUNTIFS(General!F:F, "PARA FACTURAR", General!G:G, "ENVIO DE ORDEN") -> 0
C23: MARZO | E23: =COUNTIFS(General!B:B, ">="&DATE(2025,3,1), General!B:B, "<="&DATE(2025,3,31)) -> 219 | F23: =(E23-E38)/E38 -> #DIV/0! | Q23: Ezequiel Chimento | S23: =PeritosJulio!AB44 -> 0 | V23: IP CAMIONES | W23: =COUNTIFS(General!F:F, "PARA FACTURAR", General!G:G, "IP CAMIONES") -> 0
C24: ABRIL | E24: =COUNTIFS(General!B:B, ">="&DATE(2025,4,1), General!B:B, "<="&DATE(2025,4,31)) -> 541 | F24: =(E24-E39)/E39 -> #DIV/0! | H24: TIEMPOS DE GESTION | Q24: Emiliano Delia | S24: =PeritosJulio!AB21 -> 597500 | V24: TERCEROS | W24: =COUNTIFS(General!F:F, "PARA FACTURAR", General!G:G, "TERCEROS") -> 0
C25: MAYO | E25: =COUNTIFS(General!B:B, ">="&DATE(2025,5,1), General!B:B, "<="&DATE(2025,5,31)) -> 548 | F25: =(E25-E40)/E40 -> #DIV/0! | H25: INGRESO a IP | K25: =AVERAGEIFS(General!S:S,General!B:B,">="&DATE(2025,5,1),General!B:B,"<="&DATE(2025,5,31),General!F:F,"IP CERRADA") -> 4.3580952 | Q25: Franco Rodriguez | S25: =PeritosJulio!M44 -> 0 | V25: FOTOS | W25: =COUNTIFS(General!F:F, "PARA FACTURAR", General!G:G, "FOTOS") -> 0
C26: JUNIO | E26: =COUNTIFS(General!B:B, ">="&DATE(2025,6,1), General!B:B, "<="&DATE(2025,6,31)) -> 258 | F26: =(E26-E41)/E41 -> #DIV/0! | H26: IP a CARGA | K26: =AVERAGEIFS(General!T:T,General!B:B,">="&DATE(2025,5,1),General!B:B,"<="&DATE(2025,5,31),General!F:F,"IP CERRADA") -> 1.0361905 | Q26: Gaston Di Clemente | S26: =#REF! -> #REF! | V26: IP REMOTA | W26: =COUNTIFS(General!F:F, "PARA FACTURAR", General!G:G, "IP REMOTA") -> 0
C27: JULIO | E27: =COUNTIFS(General!B:B, ">="&DATE(2025,7,1), General!B:B, "<="&DATE(2025,7,31)) -> 275 | F27: =(E27-E42)/E42 -> #DIV/0! | H27: CARGA a CIERRE | K27: =AVERAGEIFS(General!U:U,General!B:B,">="&DATE(2025,5,1),General!B:B,"<="&DATE(2025,5,31),General!F:F,"IP CERRADA") -> 174.93548 | Q27: Jairo Ferlanti | S27: =PeritosJulio!M21 -> 1234125 | V27: IP VIRTUAL | W27: =COUNTIFS(General!F:F, "PARA FACTURAR", General!G:G, "IP VIRTUAL") -> 0
C28: AGOSTO | E28: =COUNTIFS(General!B:B, ">="&DATE(2025,8,1), General!B:B, "<="&DATE(2025,8,31)) -> 194 | F28: =(E28-E43)/E43 -> #DIV/0! | H28: INGRESO a CIERRE | K28: =AVERAGEIFS(General!V:V,General!B:B,">="&DATE(2025,5,1),General!B:B,"<="&DATE(2025,5,31),General!F:F,"IP CERRADA") -> 6.5332068 | Q28: Jose Neira | S28: =#REF! -> #REF! | V28: SIN HONORARIOS | W28: =COUNTIFS(General!F:F, "PARA FACTURAR", General!G:G, "SIN HONORARIOS") -> 0
C29: SEPTIEMBRE | E29: =COUNTIFS(General!B:B, ">="&DATE(2025,9,1), General!B:B, "<="&DATE(2025,9,31)) -> 206 | F29: =(E29-E44)/E44 -> #DIV/0! | H29: IP a CIERRE | K29: =AVERAGEIFS(General!W:W,General!B:B,">="&DATE(2025,5,1),General!B:B,"<="&DATE(2025,5,31),General!F:F,"IP CERRADA") -> 175.96774 | Q29: Lucas Del Piero | S29: =PeritosJulio!W21 -> 601250 | V29: AUSENTE | W29: =COUNTIFS(General!F:F, "PARA FACTURAR", General!G:G, "AUSENTE") -> 0
C30: OCTUBRE | E30: =COUNTIFS(General!B:B, ">="&DATE(2025,10,1), General!B:B, "<="&DATE(2025,10,31)) -> 217 | F30: =(E30-E45)/E45 -> #DIV/0! | H30: Ingreso a FACT | K30: =AVERAGEIFS(General!X:X,General!B:B,">="&DATE(2025,5,1),General!B:B,"<="&DATE(2025,5,31),General!F:F,"IP CERRADA") -> 7.6228571 | Q30: Nicolas Cordova | S30: -
C31: NOVIEMBRE | E31: =COUNTIFS(General!B:B, ">="&DATE(2025,11,1), General!B:B, "<="&DATE(2025,11,31)) -> 147 | F31: =(E31-E46)/E46 -> #DIV/0! | Q31: Pablo Castillo | S31: - | V31: TOTAL PARA FACTURAR
C32: DICIEMBRE | E32: =COUNTIFS(General!B:B, ">="&DATE(2025,12,1), General!B:B, "<="&DATE(2025,12,31)) -> 189 | F32: =(E32-E47)/E47 -> #DIV/0! | Q32: TOTAL | S32: =S20+S21+S22+S23+S24+S25+S26+S27+S28+S29 -> #REF! | V32: =W18+W19+W20+W21+W22+W23+W24+W25+W26+W27+W28+W29 -> 22
C34: DERIVACIONES TOTALES 2024 | E34: =E36+E37+E38+E39+E40+E41+E42+E43+E44+E45+E46+E47 -> 0
C35: PERICIAS DERIVADAS | E35: CANTIDAD
C36: ENERO | E36: =COUNTIFS(General!B:B, ">="&DATE(2024,1,1), General!B:B, "<="&DATE(2024,1,31)) -> 0
C37: FEBRERO | E37: =COUNTIFS(General!B:B, ">="&DATE(2024,2,1), General!B:B, "<="&DATE(2024,2,31)) -> 0
C38: MARZO | E38: =COUNTIFS(General!B:B, ">="&DATE(2024,3,1), General!B:B, "<="&DATE(2024,3,31)) -> 0
C39: ABRIL | E39: =COUNTIFS(General!B:B, ">="&DATE(2024,4,1), General!B:B, "<="&DATE(2024,4,31)) -> 0
C40: MAYO | E40: =COUNTIFS(General!B:B, ">="&DATE(2024,5,1), General!B:B, "<="&DATE(2024,5,31)) -> 0
C41: JUNIO | E41: =COUNTIFS(General!B:B, ">="&DATE(2024,6,1), General!B:B, "<="&DATE(2024,6,31)) -> 0
C42: JULIO | E42: =COUNTIFS(General!B:B, ">="&DATE(2024,7,1), General!B:B, "<="&DATE(2024,7,31)) -> 0
C43: AGOSTO | E43: =COUNTIFS(General!B:B, ">="&DATE(2024,8,1), General!B:B, "<="&DATE(2024,8,31)) -> 0
...

Sheet GralAgosto
A1: s | C1: TIPO DE GESTIÓN | E1: CERRADAS | H1: LICITANDO | K1: COORDINADAS | N1: PENDIENTES | V1: VALORES ACTUALES | W1: PERICIA | X1: CARGA | Z1: (Modificar los valores de V14 y X14 para que se automatice el precio)
V2: IP CON ORDEN | W2: 5625 | X2: 5250 | Z2: PERITO - KILOMETRAJE | AB2: HONORARIOS | AC2: AOM
C4: IP CON ORDEN | E4: =COUNTIFS(General!F:F, "IP CERRADA", General!H:H, "PTE. APROBACION", General!G:G, "IP CON ORDEN", General!O:O, ">="&DATE(2025,8,1), General!O:O, "<="&DATE(2025,8,31)) -> 102 | G4: =COUNTIFS(General!F:F, "IP CERRADA", General!M:M, "A MIÑO", General!H:H, "PTE. APROBACION", General!G:G, "IP CON ORDEN", General!O:O, ">="&DATE(2025,8,1), General!O:O, "<="&DATE(2025,8,31)) -> 1 | H4: =COUNTIFS(General!F:F, "LICITANDO REPUESTOS", General!G:G, "IP CON ORDEN") -> 15 | K4: =COUNTIFS(General!F:F, "IP COORDINADA", General!G:G, "IP CON ORDEN") -> 32 | N4: SIN CONTACTAR | O4: =COUNTIFS(General!F:F, "PENDIENTE COORDINACION") -> 5 | V4: POSIBLE DT | W4: 5625 | X4: 5250 | Z4: Lucas Del Piero | AA4: =#REF! -> #REF! | AB4: =AA4*$R$14 -> #REF! | AC4: =AB4*$T$14 -> #REF!
C5: POSIBLE DT | E5: =COUNTIFS(General!F:F, "IP CERRADA", General!H:H, "PTE. APROBACION", General!G:G, "POSIBLE DT", General!O:O, ">="&DATE(2025,8,1), General!O:O, "<="&DATE(2025,8,31)) -> 8 | H5: =COUNTIFS(General!F:F, "LICITANDO REPUESTOS", General!G:G, "POSIBLE DT") -> 0 | K5: =COUNTIFS(General!F:F, "IP COORDINADA", General!G:G, "POSIBLE DT") -> 2 | N5: CONTACTADOS | O5: =COUNTIFS(General!F:F, "CONTACTADO") -> 2 | V5: IP SIN ORDEN | W5: 5625 | X5: 5250 | Z5: Alfredo Miño | AA5: =#REF! -> #REF! | AB5: =AA5*$R$14 -> #REF! | AC5: =AB5*$T$14 -> #REF!
C6: IP SIN ORDEN | E6: =COUNTIFS(General!F:F, "IP CERRADA", General!H:H, "PTE. APROBACION", General!G:G, "IP SIN ORDEN", General!O:O, ">="&DATE(2025,8,1), General!O:O, "<="&DATE(2025,8,31)) -> 39 | H6: =COUNTIFS(General!F:F, "LICITANDO REPUESTOS", General!G:G, "IP SIN ORDEN") -> 0 | K6: =COUNTIFS(General!F:F, "IP COORDINADA", General!G:G, "IP SIN ORDEN") -> 0 | N6: EN NEGOCIACIÓN | O6: =COUNTIFS(General!F:F, "PENDIENTE DE OFRECIMIENTO") -> 0 | V6: AMPLIACION | W6: 2500 | X6: 2000 | Z6: Cristian Cribari | AA6: =#REF! -> #REF! | AB6: =AA6*$R$14 -> #REF! | AC6: =AB6*$T$14 -> #REF!
C7: AMPLIACION | E7: =COUNTIFS(General!F:F, "IP CERRADA", General!H:H, "PTE. APROBACION", General!G:G, "AMPLIACION", General!O:O, ">="&DATE(2025,8,1), General!O:O, "<="&DATE(2025,8,31)) -> 23 | H7: =COUNTIFS(General!F:F, "LICITANDO REPUESTOS", General!G:G, "AMPLIACION") -> 1 | K7: =COUNTIFS(General!F:F, "IP COORDINADA", General!G:G, "AMPLIACION") -> 0 | N7: MAILS SIN RESOLVER | O7: =COUNTIFS(General!F:F, "REVISAR MAIL - SIN RESOLVER") -> 0 | V7: ENVIO DE ORDEN | W7: 0 | X7: 0 | Z7: Ezequiel Chimento | AA7: =#REF! -> #REF! | AB7: =AA7*$R$14 -> #REF! | AC7: =AB7*$T$14 -> #REF!
C8: ENVIO DE ORDEN | E8: =COUNTIFS(General!F:F, "IP CERRADA", General!H:H, "PTE. APROBACION", General!G:G, "ENVIO DE ORDEN", General!O:O, ">="&DATE(2025,8,1), General!O:O, "<="&DATE(2025,8,31)) -> 0 | H8: =COUNTIFS(General!F:F, "LICITANDO REPUESTOS", General!G:G, "ENVIO DE ORDEN") -> 0 | K8: =COUNTIFS(General!F:F, "ENVIO DE ORDEN", General!G:G, "ENVIO DE ORDEN") -> 0 | V8: AUSENTE | W8: 1500 | X8: - | Z8: Ezequiel Dzyhajlo | AA8: =#REF! -> #REF! | AB8: =AA8*$R$14 -> #REF! | AC8: =AB8*$T$14 -> #REF!
C9: IP CAMIONES | E9: =COUNTIFS(General!F:F, "IP CERRADA", General!H:H, "PTE. APROBACION", General!G:G, "IP CAMIONES", General!O:O, ">="&DATE(2025,8,1), General!O:O, "<="&DATE(2025,8,31)) -> 0 | H9: =COUNTIFS(General!F:F, "LICITANDO REPUESTOS", General!G:G, "IP CAMIONES") -> 0 | K9: =COUNTIFS(General!F:F, "IP COORDINADA", General!G:G, "IP CAMIONES") -> 0 | N9: AUSENTE | O9: =COUNTIFS(General!F:F, "IP CERRADA", General!H:H, "PTE. APROBACION", General!G:G, "AUSENTE", General!O:O, ">="&DATE(2025,8,1), General!O:O, "<="&DATE(2025,8,31)) -> 13 | V9: TERCEROS | W9: 5625 | X9: 5625 | Z9: Franco Rodriguez | AA9: =#REF! -> #REF! | AB9: =AA9*$R$14 -> #REF! | AC9: =AB9*$T$14 -> #REF!
C10: TERCEROS | E10: =COUNTIFS(General!F:F, "IP CERRADA", General!H:H, "PTE. APROBACION", General!G:G, "TERCEROS", General!O:O, ">="&DATE(2024,3,1), General!O:O, ">="&DATE(2025,8,1), General!O:O, "<="&DATE(2025,8,31)) -> 3 | H10: =COUNTIFS(General!F:F, "LICITANDO REPUESTOS", General!G:G, "TERCEROS") -> 0 | K10: =COUNTIFS(General!F:F, "IP COORDINADA", General!G:G, "TERCEROS") -> 0 | V10: FOTOS | W10: 0 | X10: 0 | Z10: Gaston Di Clemente | AA10: =#REF! -> #REF! | AB10: =AA10*$R$14 -> #REF! | AC10: =AB10*$T$14 -> #REF!
C11: FOTOS | E11: =COUNTIFS(General!F:F, "IP CERRADA", General!H:H, "PTE. APROBACION", General!G:G, "FOTOS", General!O:O, ">="&DATE(2025,8,1), General!O:O, "<="&DATE(2025,8,31)) -> 0 | H11: =COUNTIFS(General!F:F, "LICITANDO REPUESTOS", General!G:G, "FOTOS") -> 0 | K11: =COUNTIFS(General!F:F, "IP COORDINADA", General!G:G, "FOTOS") -> 0 | V11: IP REMOTA | W11: 0 | X11: 0 | Z11: Rodrigo Arin | AA11: =#REF! -> #REF! | AB11: =AA11*$R$14 -> #REF! | AC11: =AB11*$T$14 -> #REF!
C12: IP REMOTA | E12: =COUNTIFS(General!F:F, "IP CERRADA", General!H:H, "PTE. APROBACION", General!G:G, "IP REMOTA", General!O:O, ">="&DATE(2025,8,1), General!O:O, "<="&DATE(2025,8,31)) -> 0 | H12: =COUNTIFS(General!F:F, "LICITANDO REPUESTOS", General!G:G, "IP REMOTA") -> 0 | K12: =COUNTIFS(General!F:F, "IP COORDINADA", General!G:G, "IP REMOTA") -> 0 | N12: KILOMETRAJE | V12: IP CAMIONES | W12: 5625 | X12: 5250
C13: IP VIRTUAL | E13: =COUNTIFS(General!F:F, "IP CERRADA", General!H:H, "PTE. APROBACION", General!G:G, "IP VIRTUAL", General!O:O, ">="&DATE(2025,8,1), General!O:O, "<="&DATE(2025,8,31)) -> 0 | H13: =COUNTIFS(General!F:F, "LICITANDO REPUESTOS", General!G:G, "IP VIRTUAL") -> 0 | K13: =COUNTIFS(General!F:F, "IP COORDINADA", General!G:G, "IP VIRTUAL") -> 0 | N13: =SUMIFS(General!P2:P2771, General!L2:L2771, ">=01/06/2024", General!L2:L2771, "<=31/06/2024") -> 0 | V13: IP VIRTUAL | W13: - | X13: -
E14: =E4+E5+E6+E7+E8+E9+E10+E11+E12+E13 -> 175 | F14: TOTALES | H14: =H4+H5+H6+H7+H8+H9+H10+H11+H12+H13 -> 16 | I14: TOTALES | K14: =K4+K5+K6+K7+K8+K9+K10+K11+K12+K13 -> 34 | L14: TOTALES | N14: =N13*T14 -> 0
E16: TOTAL CERRADO | H16: TOTAL LICITANDO | K16: TOTAL PENDIENTE | N16: EN TRAMITE | O16: =COUNTIFS(General!H:H, "EN TRAMITE") -> 98 | V16: KM RECORRIDO | W16: 300 | X16: - | Z16: TOTAL | AA16: =AA4+AA5+AA6+AA7+AA8+AA9+AA10+AA11 -> #REF! | AB16: =AB4+AB5+AB6+AB7+AB8+AB9+AB10+AB11 -> #REF! | AC16: =AC4+AC5+AC6+AC7+AC8+AC9+AC10+AC11 -> #REF!
E17: =E4+E5+E6+E7+E8+E9+E10+E12+O9+E13 -> 188 | H17: =H4+H5+H6+H7+H8+H9+H10+H11+H12+H13 -> 16 | K17: =K4+K5+K6+K7+K8+K9+K10+K11+K12+K13 -> 34 | N17: PTE. APROBACION | O17: =COUNTIFS(General!H:H, "PTE. APROBACION") -> 3403 | Q17: (Con kilometraje ya incluido)
N18: ANULADO | O18: =COUNTIFS(General!H:H, "ANULADO") -> 198 | Q18: PERITOS | S18: HONORARIOS | V18: IP CON ORDEN | W18: =COUNTIFS(General!F:F, "PARA FACTURAR", General!G:G, "IP CON ORDEN") -> 13
C19: DERIVACIONES TOTALES 2025 | E19: =E21+E22+E23+E24+E25+E26+E27+E28+E29+E30+E31+E32 -> 3248 | H19: TOTAL POTENCIAL | N19: PARA FACTURAR | O19: =COUNTIFS(General!F:F, "PARA FACTURAR") -> 22 | V19: POSIBLE DT | W19: =COUNTIFS(General!F:F, "PARA FACTURAR", General!G:G, "POSIBLE DT") -> 2
C20: PERICIAS DERIVADAS | E20: CANTIDAD | H20: =E17+H17+K17+O19 -> 260 | Q20: Rodrigo Arin | V20: IP SIN ORDEN | W20: =COUNTIFS(General!F:F, "PARA FACTURAR", General!G:G, "IP SIN ORDEN") -> 6
C21: ENERO | E21: =COUNTIFS(General!B:B, ">="&DATE(2025,1,1), General!B:B, "<="&DATE(2025,1,31)) -> 260 | F21: =(E21-E36)/E36 -> #DIV/0! | Q21: Alfredo Miño | S21: =PeritosAgosto!H21 -> 10875 | V21: AMPLIACION | W21: =COUNTIFS(General!F:F, "PARA FACTURAR", General!G:G, "AMPLIACION") -> 1
C22: FEBRERO | E22: =COUNTIFS(General!B:B, ">="&DATE(2025,2,1), General!B:B, "<="&DATE(2025,2,31)) -> 194 | F22: =(E22-E37)/E37 -> #DIV/0! | Q22: Cristian Cribari | V22: ENVIO DE ORDEN | W22: =COUNTIFS(General!F:F, "PARA FACTURAR", General!G:G, "ENVIO DE ORDEN") -> 0
C23: MARZO | E23: =COUNTIFS(General!B:B, ">="&DATE(2025,3,1), General!B:B, "<="&DATE(2025,3,31)) -> 219 | F23: =(E23-E38)/E38 -> #DIV/0! | Q23: Ezequiel Chimento | V23: IP CAMIONES | W23: =COUNTIFS(General!F:F, "PARA FACTURAR", General!G:G, "IP CAMIONES") -> 0
C24: ABRIL | E24: =COUNTIFS(General!B:B, ">="&DATE(2025,4,1), General!B:B, "<="&DATE(2025,4,31)) -> 541 | F24: =(E24-E39)/E39 -> #DIV/0! | H24: TIEMPOS DE GESTION | Q24: Emiliano Delia | S24: =PeritosAgosto!AB21 -> 321250 | V24: TERCEROS | W24: =COUNTIFS(General!F:F, "PARA FACTURAR", General!G:G, "TERCEROS") -> 0
C25: MAYO | E25: =COUNTIFS(General!B:B, ">="&DATE(2025,5,1), General!B:B, "<="&DATE(2025,5,31)) -> 548 | F25: =(E25-E40)/E40 -> #DIV/0! | H25: INGRESO a IP | K25: =AVERAGEIFS(General!S:S,General!B:B,">="&DATE(2025,5,1),General!B:B,"<="&DATE(2025,5,31),General!F:F,"IP CERRADA") -> 4.3580952 | Q25: Franco Rodriguez | V25: FOTOS | W25: =COUNTIFS(General!F:F, "PARA FACTURAR", General!G:G, "FOTOS") -> 0
C26: JUNIO | E26: =COUNTIFS(General!B:B, ">="&DATE(2025,6,1), General!B:B, "<="&DATE(2025,6,31)) -> 258 | F26: =(E26-E41)/E41 -> #DIV/0! | H26: IP a CARGA | K26: =AVERAGEIFS(General!T:T,General!B:B,">="&DATE(2025,5,1),General!B:B,"<="&DATE(2025,5,31),General!F:F,"IP CERRADA") -> 1.0361905 | Q26: Gaston Di Clemente | V26: IP REMOTA | W26: =COUNTIFS(General!F:F, "PARA FACTURAR", General!G:G, "IP REMOTA") -> 0
C27: JULIO | E27: =COUNTIFS(General!B:B, ">="&DATE(2025,7,1), General!B:B, "<="&DATE(2025,7,31)) -> 275 | F27: =(E27-E42)/E42 -> #DIV/0! | H27: CARGA a CIERRE | K27: =AVERAGEIFS(General!U:U,General!B:B,">="&DATE(2025,5,1),General!B:B,"<="&DATE(2025,5,31),General!F:F,"IP CERRADA") -> 174.93548 | Q27: Jairo Ferlanti | S27: =PeritosAgosto!M21 -> 880125 | V27: IP VIRTUAL | W27: =COUNTIFS(General!F:F, "PARA FACTURAR", General!G:G, "IP VIRTUAL") -> 0
C28: AGOSTO | E28: =COUNTIFS(General!B:B, ">="&DATE(2025,8,1), General!B:B, "<="&DATE(2025,8,31)) -> 194 | F28: =(E28-E43)/E43 -> #DIV/0! | H28: INGRESO a CIERRE | K28: =AVERAGEIFS(General!V:V,General!B:B,">="&DATE(2025,5,1),General!B:B,"<="&DATE(2025,5,31),General!F:F,"IP CERRADA") -> 6.5332068 | Q28: Jose Neira | V28: SIN HONORARIOS | W28: =COUNTIFS(General!F:F, "PARA FACTURAR", General!G:G, "SIN HONORARIOS") -> 0
C29: SEPTIEMBRE | E29: =COUNTIFS(General!B:B, ">="&DATE(2025,9,1), General!B:B, "<="&DATE(2025,9,31)) -> 206 | F29: =(E29-E44)/E44 -> #DIV/0! | H29: IP a CIERRE | K29: =AVERAGEIFS(General!W:W,General!B:B,">="&DATE(2025,5,1),General!B:B,"<="&DATE(2025,5,31),General!F:F,"IP CERRADA") -> 175.96774 | Q29: Lucas Del Piero | S29: =PeritosAgosto!W21 -> 547500 | V29: AUSENTE | W29: =COUNTIFS(General!F:F, "PARA FACTURAR", General!G:G, "AUSENTE") -> 0
C30: OCTUBRE | E30: =COUNTIFS(General!B:B, ">="&DATE(2025,10,1), General!B:B, "<="&DATE(2025,10,31)) -> 217 | F30: =(E30-E45)/E45 -> #DIV/0! | H30: Ingreso a FACT | K30: =AVERAGEIFS(General!X:X,General!B:B,">="&DATE(2025,5,1),General!B:B,"<="&DATE(2025,5,31),General!F:F,"IP CERRADA") -> 7.6228571 | Q30: Nicolas Cordova
C31: NOVIEMBRE | E31: =COUNTIFS(General!B:B, ">="&DATE(2025,11,1), General!B:B, "<="&DATE(2025,11,31)) -> 147 | F31: =(E31-E46)/E46 -> #DIV/0! | Q31: Pablo Castillo | V31: TOTAL PARA FACTURAR
C32: DICIEMBRE | E32: =COUNTIFS(General!B:B, ">="&DATE(2025,12,1), General!B:B, "<="&DATE(2025,12,31)) -> 189 | F32: =(E32-E47)/E47 -> #DIV/0! | Q32: TOTAL | S32: =S20+S21+S22+S23+S24+S25+S26+S27+S28+S29 -> 1759750 | V32: =W18+W19+W20+W21+W22+W23+W24+W25+W26+W27+W28+W29 -> 22
C34: DERIVACIONES TOTALES 2024 | E34: =E36+E37+E38+E39+E40+E41+E42+E43+E44+E45+E46+E47 -> 0
C35: PERICIAS DERIVADAS | E35: CANTIDAD
C36: ENERO | E36: =COUNTIFS(General!B:B, ">="&DATE(2024,1,1), General!B:B, "<="&DATE(2024,1,31)) -> 0
C37: FEBRERO | E37: =COUNTIFS(General!B:B, ">="&DATE(2024,2,1), General!B:B, "<="&DATE(2024,2,31)) -> 0
C38: MARZO | E38: =COUNTIFS(General!B:B, ">="&DATE(2024,3,1), General!B:B, "<="&DATE(2024,3,31)) -> 0
C39: ABRIL | E39: =COUNTIFS(General!B:B, ">="&DATE(2024,4,1), General!B:B, "<="&DATE(2024,4,31)) -> 0
C40: MAYO | E40: =COUNTIFS(General!B:B, ">="&DATE(2024,5,1), General!B:B, "<="&DATE(2024,5,31)) -> 0
C41: JUNIO | E41: =COUNTIFS(General!B:B, ">="&DATE(2024,6,1), General!B:B, "<="&DATE(2024,6,31)) -> 0
C42: JULIO | E42: =COUNTIFS(General!B:B, ">="&DATE(2024,7,1), General!B:B, "<="&DATE(2024,7,31)) -> 0
C43: AGOSTO | E43: =COUNTIFS(General!B:B, ">="&DATE(2024,8,1), General!B:B, "<="&DATE(2024,8,31)) -> 0
...

Sheet PeritosJulio
A1: ABRIL | C1: TIPO DE GESTIÓN | E1: Alfredo Miño | J1: Jairo Ferlanti | O1: Jose Neira | T1: Lucas Del Piero | Y1: Emiliano D Elia | AD1: TIPO DE GESTIÓN
E3: PERICIAS | G3: CARGA | J3: PERICIAS | L3: CARGA | O3: PERICIAS | Q3: CARGA | T3: PERICIAS | V3: CARGA | Y3: PERICIAS | AA3: CARGA
C4: IP CON ORDEN | E4: =COUNTIFS(General!F:F, "IP CERRADA", General!K:K, "A MIÑO", General!H:H, "PTE. APROBACION", General!G:G, "IP CON ORDEN", General!O:O, ">="&DATE(2025,7,1), General!O:O, "<="&DATE(2025,7,31)) -> 0 | F4: =E4*AG5 -> 0 | G4: =COUNTIFS(General!F:F, "IP CERRADA", General!M:M, "A MIÑO", General!H:H, "PTE. APROBACION", General!G:G, "IP CON ORDEN", General!O:O, ">="&DATE(2025,7,1), General!O:O, "<="&DATE(2025,7,31)) -> 0 | H4: =G4*AH5 -> 0 | J4: =COUNTIFS(General!F:F, "IP CERRADA", General!K:K, "J. FERLANTI", General!H:H, "PTE. APROBACION", General!G:G, "IP CON ORDEN", General!O:O, ">="&DATE(2025,7,1), General!O:O, "<="&DATE(2025,7,31)) + COUNTIFS(General!F:F, "PARA FACTURAR", General!K:K, "J. FERLANTI", General!G:G, "IP CON ORDEN", General!O:O, ">="&DATE(2025,7,1), General!O:O, "<="&DATE(2025,7,31)) -> 1 | K4: =J4*AG5 -> 5625 | L4: =COUNTIFS(General!F:F, "IP CERRADA", General!M:M, "J. FERLANTI", General!H:H, "PTE. APROBACION", General!G:G, "IP CON ORDEN", General!O:O, ">="&DATE(2025,7,1), General!O:O, "<="&DATE(2025,7,31)) + COUNTIFS(General!F:F, "PARA FACTURAR", General!M:M, "J. FERLANTI", General!H:H, "EN TRAMITE", General!G:G, "IP CON ORDEN", General!O:O, ">="&DATE(2024,10,1), General!O:O, "<="&DATE(2024,10,31) ) -> 142 | M4: =L4*AH5 -> 745500 | O4: =COUNTIFS(General!F:F, "IP CERRADA", General!K:K, "J NEIRA", General!H:H, "PTE. APROBACION", General!G:G, "IP CON ORDEN", General!O:O, ">="&DATE(2025,7,1), General!O:O, "<="&DATE(2025,7,31)) -> 0 | P4: =O4*AG5 -> 0 | Q4: =COUNTIFS(General!F:F, "IP CERRADA", General!M:M, "J NEIRA", General!H:H, "PTE. APROBACION", General!G:G, "IP CON ORDEN", General!O:O, ">="&DATE(2025,7,1), General!O:O, "<="&DATE(2025,7,31)) -> 0 | R4: =Q4*AH5 -> 0 | T4: =COUNTIFS(General!F:F, "IP CERRADA", General!K:K, "L DEL PIERO", General!H:H, "PTE. APROBACION", General!G:G, "IP CON ORDEN", General!O:O, ">="&DATE(2025,7,1), General!O:O, "<="&DATE(2025,7,31)) -> 74 | U4: =T4*AG5 -> 416250 | V4: =COUNTIFS(General!F:F, "IP CERRADA", General!M:M, "L DEL PIERO", General!H:H, "PTE. APROBACION", General!G:G, "IP CON ORDEN", General!O:O, ">="&DATE(2025,7,1), General!O:O, "<="&DATE(2025,7,31)) -> 0 | W4: =V4*AH5 -> 0 | Y4: =COUNTIFS(General!F:F, "IP CERRADA", General!K:K, "E Delia", General!H:H, "PTE. APROBACION", General!G:G, "IP CON ORDEN", General!O:O, ">="&DATE(2025,7,1), General!O:O, "<="&DATE(2025,7,31)) + COUNTIFS(General!F:F, "PARA FACTURAR", General!K:K, "E Delia", General!G:G, "IP CON ORDEN", General!O:O, ">="&DATE(2025,7,1), General!O:O, "<="&DATE(2025,7,31)) -> 67 | Z4: =Y4*AG5 -> 376875 | AA4: =COUNTIFS(General!F:F, "IP CERRADA", General!M:M, "E Delia", General!H:H, "PTE. APROBACION", General!G:G, "IP CON ORDEN", General!O:O, ">="&DATE(2025,7,1), General!O:O, "<="&DATE(2025,7,31)) -> 0 | AB4: =AA4*AH5 -> 0 | AD4: IP CON ORDEN | AF4: VALORES ACTUALES | AG4: PERICIA | AH4: CARGA
C5: POSIBLE DT | E5: =COUNTIFS(General!F:F, "IP CERRADA", General!K:K, "A MIÑO", General!H:H, "PTE. APROBACION", General!G:G, "POSIBLE DT", General!O:O, ">="&DATE(2025,7,1), General!O:O, "<="&DATE(2025,7,31)) -> 0 | F5: =E5*AG7 -> 0 | G5: =COUNTIFS(General!F:F, "IP CERRADA", General!M:M, "A MIÑO", General!H:H, "PTE. APROBACION", General!G:G, "POSIBLE DT", General!O:O, ">="&DATE(2025,7,1), General!O:O, "<="&DATE(2025,7,31)) -> 0 | H5: =G5*AH7 -> 0 | J5: =COUNTIFS(General!F:F, "IP CERRADA", General!K:K, "J. FERLANTI", General!H:H, "PTE. APROBACION", General!G:G, "POSIBLE DT", General!O:O, ">="&DATE(2025,7,1), General!O:O, "<="&DATE(2025,7,31)) + COUNTIFS(General!F:F, "PARA FACTURAR", General!K:K, "J. FERLANTI", General!G:G, "POSIBLE DT", General!O:O, ">="&DATE(2025,7,1), General!O:O, "<="&DATE(2025,7,31)) -> 1 | K5: =J5*AG7 -> 5625 | L5: =COUNTIFS(General!F:F, "IP CERRADA", General!M:M, "J. FERLANTI", General!H:H, "PTE. APROBACION", General!G:G, "POSIBLE DT", General!O:O, ">="&DATE(2025,7,1), General!O:O, "<="&DATE(2025,7,31)) + COUNTIFS(General!F:F, "PARA FACTURAR", General!M:M, "J. FERLANTI", General!H:H, "EN TRAMITE", General!G:G, "POSIBLE DT", General!O:O, ">="&DATE(2025,7,1), General!O:O, "<="&DATE(2025,7,31)) -> 12 | M5: =L5*AH7 -> 63000 | O5: =COUNTIFS(General!F:F, "IP CERRADA", General!K:K, "J NEIRA", General!H:H, "PTE. APROBACION", General!G:G, "POSIBLE DT", General!O:O, ">="&DATE(2025,7,1), General!O:O, "<="&DATE(2025,7,31)) -> 0 | P5: =O5*AG7 -> 0 | Q5: =COUNTIFS(General!F:F, "IP CERRADA", General!M:M, "J NEIRA", General!H:H, "PTE. APROBACION", General!G:G, "POSIBLE DT", General!O:O, ">="&DATE(2025,7,1), General!O:O, "<="&DATE(2025,7,31)) -> 0 | R5: =Q5*AH7 -> 0 | T5: =COUNTIFS(General!F:F, "IP CERRADA", General!K:K, "L DEL PIERO", General!H:H, "PTE. APROBACION", General!G:G, "POSIBLE DT", General!O:O, ">="&DATE(2025,7,1), General!O:O, "<="&DATE(2025,7,31)) -> 3 | U5: =T5*AG7 -> 16875 | V5: =COUNTIFS(General!F:F, "IP CERRADA", General!M:M, "L DEL PIERO", General!H:H, "PTE. APROBACION", General!G:G, "POSIBLE DT", General!O:O, ">="&DATE(2025,7,1), General!O:O, "<="&DATE(2025,7,31)) -> 0 | W5: =V5*AH7 -> 0 | Y5: =COUNTIFS(General!F:F, "IP CERRADA", General!K:K, "E Delia", General!H:H, "PTE. APROBACION", General!G:G, "POSIBLE DT", General!O:O, ">="&DATE(2025,7,1), General!O:O, "<="&DATE(2025,7,31)) -> 8 | Z5: =Y5*AG7 -> 45000 | AA5: =COUNTIFS(General!F:F, "IP CERRADA", General!M:M, "E Delia", General!H:H, "PTE. APROBACION", General!G:G, "POSIBLE DT", General!O:O, ">="&DATE(2025,7,1), General!O:O, "<="&DATE(2025,7,31)) -> 0 | AB5: =AA5*AH7 -> 0 | AD5: POSIBLE DT | AF5: IP CON ORDEN | AG5: 5625 | AH5: 5250
C6: IP SIN ORDEN | E6: =COUNTIFS(General!F:F, "IP CERRADA", General!K:K, "A MIÑO", General!H:H, "PTE. APROBACION", General!G:G, "IP SIN ORDEN", General!O:O, ">="&DATE(2025,7,1), General!O:O, "<="&DATE(2025,7,31)) -> 2 | F6: =E6*AG8 -> 11250 | G6: =COUNTIFS(General!F:F, "IP CERRADA", General!M:M, "A MIÑO", General!H:H, "PTE. APROBACION", General!G:G, "IP SIN ORDEN", General!O:O, ">="&DATE(2025,7,1), General!O:O, "<="&DATE(2025,7,31)) -> 0 | H6: =G6*AH8 -> 0 | J6: =COUNTIFS(General!F:F, "IP CERRADA", General!K:K, "J. FERLANTI", General!H:H, "PTE. APROBACION", General!G:G, "IP SIN ORDEN", General!O:O, ">="&DATE(2025,7,1), General!O:O, "<="&DATE(2025,7,31)) + COUNTIFS(General!F:F, "PARA FACTURAR", General!K:K, "J. FERLANTI", General!G:G, "IP SIN ORDEN", General!O:O, ">="&DATE(2025,7,1), General!O:O, "<="&DATE(2025,7,31)) -> 3 | K6: =J6*AG8 -> 16875 | L6: =COUNTIFS(General!F:F, "IP CERRADA", General!M:M, "J. FERLANTI", General!H:H, "PTE. APROBACION", General!G:G, "IP SIN ORDEN", General!O:O, ">="&DATE(2025,7,1), General!O:O, "<="&DATE(2025,7,31)) + COUNTIFS(General!F:F, "PARA FACTURAR", General!M:M, "J. FERLANTI", General!H:H, "EN TRAMITE", General!G:G, "IP SIN ORDEN", General!O:O, ">="&DATE(2025,7,1), General!O:O, "<="&DATE(2025,7,31)) -> 59 | M6: =L6*AH8 -> 309750 | O6: =COUNTIFS(General!F:F, "IP CERRADA", General!K:K, "J NEIRA", General!H:H, "PTE. APROBACION", General!G:G, "IP SIN ORDEN", General!O:O, ">="&DATE(2025,7,1), General!O:O, "<="&DATE(2025,7,31)) -> 0 | P6: =O6*AG8 -> 0 | Q6: =COUNTIFS(General!F:F, "IP CERRADA", General!M:M, "J NEIRA", General!H:H, "PTE. APROBACION", General!G:G, "IP SIN ORDEN", General!O:O, ">="&DATE(2025,7,1), General!O:O, "<="&DATE(2025,7,31)) -> 0 | R6: =Q6*AH8 -> 0 | T6: =COUNTIFS(General!F:F, "IP CERRADA", General!K:K, "L DEL PIERO", General!H:H, "PTE. APROBACION", General!G:G, "IP SIN ORDEN", General!O:O, ">="&DATE(2025,7,1), General!O:O, "<="&DATE(2025,7,31)) -> 25 | U6: =T6*AG8 -> 140625 | V6: =COUNTIFS(General!F:F, "IP CERRADA", General!M:M, "L DEL PIERO", General!H:H, "PTE. APROBACION", General!G:G, "IP SIN ORDEN", General!O:O, ">="&DATE(2025,7,1), General!O:O, "<="&DATE(2025,7,31)) -> 0 | W6: =V6*AH8 -> 0 | Y6: =COUNTIFS(General!F:F, "IP CERRADA", General!K:K, "E Delia", General!H:H, "PTE. APROBACION", General!G:G, "IP SIN ORDEN", General!O:O, ">="&DATE(2025,7,1), General!O:O, "<="&DATE(2025,7,31)) -> 29 | Z6: =Y6*AG8 -> 163125 | AA6: =COUNTIFS(General!F:F, "IP CERRADA", General!M:M, "E Delia", General!H:H, "PTE. APROBACION", General!G:G, "IP SIN ORDEN", General!O:O, ">="&DATE(2025,7,1), General!O:O, "<="&DATE(2025,7,31)) -> 0 | AB6: =AA6*AH8 -> 0 | AD6: IP SIN ORDEN
C7: AMPLIACION | E7: =COUNTIFS(General!F:F, "IP CERRADA", General!K:K, "A MIÑO", General!H:H, "PTE. APROBACION", General!G:G, "AMPLIACION", General!O:O, ">="&DATE(2025,7,1), General!O:O, "<="&DATE(2025,7,31)) -> 0 | F7: =E7*AG9 -> 0 | G7: =COUNTIFS(General!F:F, "IP CERRADA", General!M:M, "A MIÑO", General!H:H, "PTE. APROBACION", General!G:G, "AMPLIACION", General!O:O, ">="&DATE(2025,7,1), General!O:O, "<="&DATE(2025,7,31)) -> 0 | H7: =G7*AH9 -> 0 | J7: =COUNTIFS(General!F:F, "IP CERRADA", General!K:K, "J. FERLANTI", General!H:H, "PTE. APROBACION", General!G:G, "AMPLIACION", General!O:O, ">="&DATE(2025,7,1), General!O:O, "<="&DATE(2025,7,31)) + COUNTIFS(General!F:F, "PARA FACTURAR", General!K:K, "J. FERLANTI", General!G:G, "AMPLIACION", General!O:O, ">="&DATE(2025,7,1), General!O:O, "<="&DATE(2025,7,31)) -> 9 | K7: =J7*AG9 -> 22500 | L7: =COUNTIFS(General!F:F, "IP CERRADA", General!M:M, "J. FERLANTI", General!H:H, "PTE. APROBACION", General!G:G, "AMPLIACION", General!O:O, ">="&DATE(2025,7,1), General!O:O, "<="&DATE(2025,7,31)) + COUNTIFS(General!F:F, "PARA FACTURAR", General!M:M, "J. FERLANTI", General!H:H, "EN TRAMITE", General!G:G, "AMPLIACION", General!O:O, ">="&DATE(2025,7,1), General!O:O, "<="&DATE(2025,7,31)) -> 25 | M7: =L7*AH9 -> 50000 | O7: =COUNTIFS(General!F:F, "IP CERRADA", General!K:K, "J NEIRA", General!H:H, "PTE. APROBACION", General!G:G, "AMPLIACION", General!O:O, ">="&DATE(2025,7,1), General!O:O, "<="&DATE(2025,7,31)) -> 0 | P7: =O7*AG9 -> 0 | Q7: =COUNTIFS(General!F:F, "IP CERRADA", General!M:M, "J NEIRA", General!H:H, "PTE. APROBACION", General!G:G, "AMPLIACION", General!O:O, ">="&DATE(2025,7,1), General!O:O, "<="&DATE(2025,7,31)) -> 0 | R7: =Q7*AH9 -> 0 | T7: =COUNTIFS(General!F:F, "IP CERRADA", General!K:K, "L DEL PIERO", General!H:H, "PTE. APROBACION", General!G:G, "AMPLIACION", General!O:O, ">="&DATE(2025,7,1), General!O:O, "<="&DATE(2025,7,31)) -> 11 | U7: =T7*AG9 -> 27500 | V7: =COUNTIFS(General!F:F, "IP CERRADA", General!M:M, "L DEL PIERO", General!H:H, "PTE. APROBACION", General!G:G, "AMPLIACION", General!O:O, ">="&DATE(2025,7,1), General!O:O, "<="&DATE(2025,7,31)) -> 0 | W7: =V7*AH9 -> 0 | Y7: =COUNTIFS(General!F:F, "IP CERRADA", General!K:K, "E Delia", General!H:H, "PTE. APROBACION", General!G:G, "AMPLIACION", General!O:O, ">="&DATE(2025,7,1), General!O:O, "<="&DATE(2025,7,31)) -> 5 | Z7: =Y7*AG9 -> 12500 | AA7: =COUNTIFS(General!F:F, "IP CERRADA", General!M:M, "E Delia", General!H:H, "PTE. APROBACION", General!G:G, "AMPLIACION", General!O:O, ">="&DATE(2025,7,1), General!O:O, "<="&DATE(2025,7,31)) -> 0 | AB7: =AA7*AH9 -> 0 | AD7: AMPLIACION | AF7: POSIBLE DT | AG7: 5625 | AH7: 5250
C8: ENVIO DE ORDEN | E8: - | F8: - | G8: =COUNTIFS(General!F:F, "IP CERRADA", General!M:M, "A MIÑO", General!H:H, "PTE. APROBACION", General!G:G, "ENVIO DE ORDEN", General!O:O, ">="&DATE(2025,7,1), General!O:O, "<="&DATE(2025,7,31)) -> 0 | H8: =G8*AH10 -> 0 | J8: - | K8: - | L8: =COUNTIFS(General!F:F, "IP SIN ORDEN", General!M:M, "J. FERLANTI", General!H:H, "PTE. APROBACION", General!G:G, "ENVIO DE ORDEN", General!O:O, ">="&DATE(2025,7,1), General!O:O, "<="&DATE(2025,7,31)) + COUNTIFS(General!F:F, "PARA FACTURAR", General!M:M, "J. FERLANTI", General!H:H, "EN TRAMITE", General!G:G, "ENVIO DE ORDEN", General!O:O, ">="&DATE(2025,7,1), General!O:O, "<="&DATE(2025,7,31)) -> 0 | M8: =L8*AH10 -> 0 | Q8: =COUNTIFS(General!F:F, "IP CERRADA", General!M:M, "J NEIRA", General!H:H, "PTE. APROBACION", General!G:G, "ENVIO DE ORDEN", General!O:O, ">="&DATE(2025,7,1), General!O:O, "<="&DATE(2025,7,31)) -> 0 | R8: =Q8*AH10 -> 0 | V8: =COUNTIFS(General!F:F, "IP CERRADA", General!M:M, "L DEL PIERO", General!H:H, "PTE. APROBACION", General!G:G, "ENVIO DE ORDEN", General!O:O, ">="&DATE(2025,7,1), General!O:O, "<="&DATE(2025,7,31)) -> 0 | W8: =V8*AH10 -> 0 | AA8: =COUNTIFS(General!F:F, "IP CERRADA", General!M:M, "E Delia", General!H:H, "PTE. APROBACION", General!G:G, "ENVIO DE ORDEN", General!O:O, ">="&DATE(2025,7,1), General!O:O, "<="&DATE(2025,7,31)) -> 0 | AB8: =AA8*AH10 -> 0 | AD8: ENVIO DE ORDEN | AF8: IP SIN ORDEN | AG8: 5625 | AH8: 5250
C9: IP CAMIONES | E9: =COUNTIFS(General!F:F, "IP CERRADA", General!K:K, "A MIÑO", General!H:H, "PTE. APROBACION", General!G:G, "IP CAMIONES", General!O:O, ">="&DATE(2025,7,1), General!O:O, "<="&DATE(2025,7,31)) -> 0 | F9: =E9*AG15 -> 0 | G9: =COUNTIFS(General!F:F, "IP SIN ORDEN", General!M:M, "J. FERLANTI", General!H:H, "PTE. APROBACION", General!G:G, "IP CAMIONES", General!O:O, ">="&DATE(2025,7,1), General!O:O, "<="&DATE(2025,7,31)) + COUNTIFS(General!F:F, "PARA FACTURAR", General!M:M, "J. FERLANTI", General!H:H, "EN TRAMITE", General!G:G, "IP CAMIONES", General!O:O, ">="&DATE(2025,7,1), General!O:O, "<="&DATE(2025,7,31)) -> 0 | H9: =G9*AH15 -> 0 | J9: =COUNTIFS(General!F:F, "IP CERRADA", General!K:K, "J. FERLANTI", General!H:H, "PTE. APROBACION", General!G:G, "IP CAMIONES", General!O:O, ">="&DATE(2025,7,1), General!O:O, "<="&DATE(2025,7,31)) + COUNTIFS(General!F:F, "PARA FACTURAR", General!K:K, "J. FERLANTI", General!G:G, "IP CAMIONES", General!O:O, ">="&DATE(2025,7,1), General!O:O, "<="&DATE(2025,7,31)) -> 0 | K9: =J9*AG15 -> 0 | L9: =COUNTIFS(General!F:F, "IP CERRADA", General!M:M, "J. FERLANTI", General!H:H, "PTE. APROBACION", General!G:G, "IP CAMIONES", General!O:O, ">="&DATE(2025,7,1), General!O:O, "<="&DATE(2025,7,31)) -> 0 | M9: =L9*AH15 -> 0 | O9: =COUNTIFS(General!F:F, "IP CERRADA", General!K:K, "J NEIRA", General!H:H, "PTE. APROBACION", General!G:G, "IP CAMIONES", General!O:O, ">="&DATE(2025,7,1), General!O:O, "<="&DATE(2025,7,31)) -> 0 | P9: =O9*AG15 -> 0 | Q9: =COUNTIFS(General!F:F, "IP CERRADA", General!M:M, "J NEIRA", General!H:H, "PTE. APROBACION", General!G:G, "IP CAMIONES", General!O:O, ">="&DATE(2025,7,1), General!O:O, "<="&DATE(2025,7,31)) -> 0 | R9: =Q9*AH15 -> 0 | T9: =COUNTIFS(General!F:F, "IP CERRADA", General!K:K, "L DEL PIERO", General!H:H, "PTE. APROBACION", General!G:G, "IP CAMIONES", General!O:O, ">="&DATE(2025,7,1), General!O:O, "<="&DATE(2025,7,31)) -> 0 | U9: =T9*AG15 -> 0 | V9: =COUNTIFS(General!F:F, "IP CERRADA", General!M:M, "L DEL PIERO", General!H:H, "PTE. APROBACION", General!G:G, "IP CAMIONES", General!O:O, ">="&DATE(2025,7,1), General!O:O, "<="&DATE(2025,7,31)) -> 0 | W9: =V9*AH15 -> 0 | Y9: =COUNTIFS(General!F:F, "IP CERRADA", General!K:K, "E Delia", General!H:H, "PTE. APROBACION", General!G:G, "IP CAMIONES", General!O:O, ">="&DATE(2025,7,1), General!O:O, "<="&DATE(2025,7,31)) -> 0 | Z9: =Y9*AG15 -> 0 | AA9: =COUNTIFS(General!F:F, "IP CERRADA", General!M:M, "E Delia", General!H:H, "PTE. APROBACION", General!G:G, "IP CAMIONES", General!O:O, ">="&DATE(2025,7,1), General!O:O, "<="&DATE(2025,7,31)) -> 0 | AB9: =AA9*AH15 -> 0 | AD9: IP CAMIONES | AF9: AMPLIACION | AG9: 2500 | AH9: 2000
C10: TERCEROS | E10: =COUNTIFS(General!F:F, "IP CERRADA", General!K:K, "A MIÑO", General!H:H, "PTE. APROBACION", General!G:G, "TERCEROS", General!O:O, ">="&DATE(2024,3,1), General!O:O, ">="&DATE(2025,7,1), General!O:O, "<="&DATE(2025,7,31)) -> 0 | F10: =E10*AG12 -> 0 | G10: =COUNTIFS(General!F:F, "IP CERRADA", General!M:M, "A MIÑO", General!H:H, "PTE. APROBACION", General!G:G, "TERCEROS", General!O:O, ">="&DATE(2025,7,1), General!O:O, "<="&DATE(2025,7,31)) -> 0 | H10: =G10*AH12 -> 0 | J10: =COUNTIFS(General!F:F, "IP CERRADA", General!K:K, "J. FERLANTI", General!H:H, "PTE. APROBACION", General!G:G, "TERCEROS", General!O:O, ">="&DATE(2025,7,1), General!O:O, "<="&DATE(2025,7,31)) + COUNTIFS(General!F:F, "PARA FACTURAR", General!K:K, "J. FERLANTI", General!G:G, "TERCEROS", General!O:O, ">="&DATE(2025,7,1), General!O:O, "<="&DATE(2025,7,31)) -> 2 | K10: =J10*AG12 -> 11250 | L10: =COUNTIFS(General!F:F, "IP SIN ORDEN", General!M:M, "J. FERLANTI", General!H:H, "PTE. APROBACION", General!G:G, "TERCEROS", General!O:O, ">="&DATE(2025,7,1), General!O:O, "<="&DATE(2025,7,31)) + COUNTIFS(General!F:F, "PARA FACTURAR", General!M:M, "J. FERLANTI", General!H:H, "EN TRAMITE", General!G:G, "TERCEROS", General!O:O, ">="&DATE(2025,7,1), General!O:O, "<="&DATE(2025,7,31)) -> 0 | M10: =L10*AH12 -> 0 | O10: =COUNTIFS(General!F:F, "IP CERRADA", General!K:K, "J NEIRA", General!H:H, "PTE. APROBACION", General!G:G, "TERCEROS", General!O:O, ">="&DATE(2024,3,1), General!O:O, ">="&DATE(2025,7,1), General!O:O, "<="&DATE(2025,7,31)) -> 0 | P10: =O10*AG12 -> 0 | Q10: =COUNTIFS(General!F:F, "IP CERRADA", General!M:M, "J NEIRA", General!H:H, "PTE. APROBACION", General!G:G, "TERCEROS", General!O:O, ">="&DATE(2025,7,1), General!O:O, "<="&DATE(2025,7,31)) -> 0 | R10: =Q10*AH12 -> 0 | T10: =COUNTIFS(General!F:F, "IP CERRADA", General!K:K, "L DEL PIERO", General!H:H, "PTE. APROBACION", General!G:G, "TERCEROS", General!O:O, ">="&DATE(2024,3,1), General!O:O, ">="&DATE(2025,7,1), General!O:O, "<="&DATE(2025,7,31)) -> 0 | U10: =T10*AG12 -> 0 | V10: =COUNTIFS(General!F:F, "IP CERRADA", General!M:M, "L DEL PIERO", General!H:H, "PTE. APROBACION", General!G:G, "TERCEROS", General!O:O, ">="&DATE(2025,7,1), General!O:O, "<="&DATE(2025,7,31)) -> 0 | W10: =V10*AH12 -> 0 | Y10: =COUNTIFS(General!F:F, "IP CERRADA", General!K:K, "E Delia", General!H:H, "PTE. APROBACION", General!G:G, "TERCEROS", General!O:O, ">="&DATE(2024,3,1), General!O:O, ">="&DATE(2025,7,1), General!O:O, "<="&DATE(2025,7,31)) -> 0 | Z10: =Y10*AG12 -> 0 | AA10: =COUNTIFS(General!F:F, "IP CERRADA", General!M:M, "E Delia", General!H:H, "PTE. APROBACION", General!G:G, "TERCEROS", General!O:O, ">="&DATE(2025,7,1), General!O:O, "<="&DATE(2025,7,31)) -> 0 | AB10: =AA10*AH12 -> 0 | AD10: TERCEROS | AF10: ENVIO DE ORDEN | AG10: -
C11: FOTOS | E11: - | F11: - | G11: =COUNTIFS(General!F:F, "IP CERRADA", General!M:M, "A MIÑO", General!H:H, "PTE. APROBACION", General!G:G, "FOTOS", General!O:O, ">="&DATE(2025,7,1), General!O:O, "<="&DATE(2025,7,31)) -> 0 | H11: 0 | J11: - | K11: - | L11: =COUNTIFS(General!F:F, "IP SIN ORDEN", General!M:M, "J. FERLANTI", General!H:H, "PTE. APROBACION", General!G:G, "FOTOS", General!O:O, ">="&DATE(2025,7,1), General!O:O, "<="&DATE(2025,7,31)) + COUNTIFS(General!F:F, "PARA FACTURAR", General!M:M, "J. FERLANTI", General!H:H, "EN TRAMITE", General!G:G, "FOTOS", General!O:O, ">="&DATE(2025,7,1), General!O:O, "<="&DATE(2025,7,31)) -> 0 | M11: =L11*AH13 -> 0 | Q11: =COUNTIFS(General!F:F, "IP CERRADA", General!M:M, "J NEIRA", General!H:H, "PTE. APROBACION", General!G:G, "FOTOS", General!O:O, ">="&DATE(2025,7,1), General!O:O, "<="&DATE(2025,7,31)) -> 0 | R11: =Q11*AH13 -> 0 | V11: =COUNTIFS(General!F:F, "IP CERRADA", General!M:M, "L DEL PIERO", General!H:H, "PTE. APROBACION", General!G:G, "FOTOS", General!O:O, ">="&DATE(2025,7,1), General!O:O, "<="&DATE(2025,7,31)) -> 0 | W11: =V11*AH13 -> 0 | AA11: =COUNTIFS(General!F:F, "IP CERRADA", General!M:M, "E Delia", General!H:H, "PTE. APROBACION", General!G:G, "FOTOS", General!O:O, ">="&DATE(2025,7,1), General!O:O, "<="&DATE(2025,7,31)) -> 0 | AB11: =AA11*AH13 -> 0 | AD11: FOTOS | AF11: AUSENTE | AG11: 1650 | AH11: -
C12: INTERMEDIA/FINAL | E12: =COUNTIFS(General!F:F, "IP CERRADA", General!K:K, "A MIÑO", General!K:K, "A MIÑO", General!H:H, "PTE. APROBACION", General!G:G, "IP FINAL/INTERMEDIA", General!O:O, ">="&DATE(2025,7,1), General!O:O, "<="&DATE(2025,7,31)) -> 0 | F12: =E12*AG14 -> 0 | G12: =COUNTIFS(General!F:F, "IP CERRADA", General!M:M, "A MIÑO", General!H:H, "PTE. APROBACION", General!G:G, "IP REMOTA", General!O:O, ">="&DATE(2025,7,1), General!O:O, "<="&DATE(2025,7,31)) -> 0 | H12: =G12*AH14 -> 0 | J12: =COUNTIFS(General!F:F, "IP CERRADA", General!K:K, "J. FERLANTI", General!H:H, "PTE. APROBACION", General!G:G, "IP FINAL/INTERMEDIA", General!O:O, ">="&DATE(2025,7,1), General!O:O, "<="&DATE(2025,7,31)) + COUNTIFS(General!F:F, "PARA FACTURAR", General!K:K, "J. FERLANTI", General!G:G, "IP FINAL/INTERMEDIA", General!O:O, ">="&DATE(2025,7,1), General!O:O, "<="&DATE(2025,7,31)) -> 0 | K12: =J12*AG9 -> 0 | L12: =COUNTIFS(General!F:F, "IP CERRADA", General!M:M, "J. FERLANTI", General!H:H, "PTE. APROBACION", General!G:G, "IP FINAL/INTERMEDIA", General!O:O, ">="&DATE(2025,7,1), General!O:O, "<="&DATE(2025,7,31)) + COUNTIFS(General!F:F, "PARA FACTURAR", General!M:M, "J. FERLANTI", General!H:H, "EN TRAMITE", General!G:G, "IP FINAL/INTERMEDIA", General!O:O, ">="&DATE(2025,7,1), General!O:O, "<="&DATE(2025,7,31)) -> 2 | M12: =L12*AH9 -> 4000 | O12: =COUNTIFS(General!F:F, "IP CERRADA", General!K:K, "J NEIRA", General!K:K, "A MIÑO", General!H:H, "PTE. APROBACION", General!G:G, "IP REMOTA", General!O:O, ">="&DATE(2025,7,1), General!O:O, "<="&DATE(2025,7,31)) -> 0 | P12: =O12*AG14 -> 0 | Q12: =COUNTIFS(General!F:F, "IP CERRADA", General!M:M, "J NEIRA", General!H:H, "PTE. APROBACION", General!G:G, "IP REMOTA", General!O:O, ">="&DATE(2025,7,1), General!O:O, "<="&DATE(2025,7,31)) -> 0 | R12: =Q12*AH14 -> 0 | T12: =COUNTIFS(General!F:F, "IP CERRADA", General!K:K, "L DEL PIERO", General!K:K, "A MIÑO", General!H:H, "PTE. APROBACION", General!G:G, "IP REMOTA", General!O:O, ">="&DATE(2025,7,1), General!O:O, "<="&DATE(2025,7,31)) -> 0 | U12: =T12*AG14 -> 0 | V12: =COUNTIFS(General!F:F, "IP CERRADA", General!M:M, "L DEL PIERO", General!H:H, "PTE. APROBACION", General!G:G, "IP REMOTA", General!O:O, ">="&DATE(2025,7,1), General!O:O, "<="&DATE(2025,7,31)) -> 0 | W12: =V12*AH14 -> 0 | Y12: =COUNTIFS(General!F:F, "IP CERRADA", General!K:K, "E Delia", General!H:H, "PTE. APROBACION", General!G:G, "IP FINAL/INTERMEDIA", General!O:O, ">="&DATE(2025,7,1), General!O:O, "<="&DATE(2025,7,31)) -> 0 | Z12: =Y12*AG9 -> 0 | AA12: =COUNTIFS(General!F:F, "IP CERRADA", General!M:M, "E Delia", General!H:H, "PTE. APROBACION", General!G:G, "IP REMOTA", General!O:O, ">="&DATE(2025,7,1), General!O:O, "<="&DATE(2025,7,31)) -> 0 | AB12: =AA12*AH14 -> 0 | AD12: IP REMOTA | AF12: TERCEROS | AG12: 5625 | AH12: 5250
C13: IP VIRTUAL | E13: - | F13: - | G13: =COUNTIFS(General!F:F, "IP CERRADA", General!M:M, "A MIÑO", General!H:H, "PTE. APROBACION", General!G:G, "IP VIRTUAL", General!O:O, ">="&DATE(2025,7,1), General!O:O, "<="&DATE(2025,7,31)) -> 0 | H13: =G13*AH16 -> 0 | J13: - | K13: - | L13: =COUNTIFS(General!F:F, "IP SIN ORDEN", General!M:M, "J. FERLANTI", General!H:H, "PTE. APROBACION", General!G:G, "IP VIRTUAL", General!O:O, ">="&DATE(2025,7,1), General!O:O, "<="&DATE(2025,7,31)) + COUNTIFS(General!F:F, "PARA FACTURAR", General!M:M, "J. FERLANTI", General!H:H, "EN TRAMITE", General!G:G, "IP VIRTUAL", General!O:O, ">="&DATE(2025,7,1), General!O:O, "<="&DATE(2025,7,31)) -> 0 | M13: =L13*AH16 -> 0 | Q13: =COUNTIFS(General!F:F, "IP CERRADA", General!M:M, "J NEIRA", General!H:H, "PTE. APROBACION", General!G:G, "IP VIRTUAL", General!O:O, ">="&DATE(2025,7,1), General!O:O, "<="&DATE(2025,7,31)) -> 0 | R13: =Q13*AH16 -> 0 | V13: =COUNTIFS(General!F:F, "IP CERRADA", General!M:M, "L DEL PIERO", General!H:H, "PTE. APROBACION", General!G:G, "IP VIRTUAL", General!O:O, ">="&DATE(2025,7,1), General!O:O, "<="&DATE(2025,7,31)) -> 0 | W13: =V13*AH16 -> 0 | AA13: =COUNTIFS(General!F:F, "IP CERRADA", General!M:M, "E Delia", General!H:H, "PTE. APROBACION", General!G:G, "IP VIRTUAL", General!O:O, ">="&DATE(2025,7,1), General!O:O, "<="&DATE(2025,7,31)) -> 0 | AB13: =AA13*AH16 -> 0 | AD13: IP VIRTUAL | AF13: FOTOS | AG13: - | AH13: 0
C14: AUSENTE | E14: =COUNTIFS(General!F:F, "IP CERRADA", General!K:K, "A MIÑO", General!K:K, "A MIÑO", General!H:H, "PTE. APROBACION", General!G:G, "AUSENTE", General!O:O, ">="&DATE(2025,7,1), General!O:O, "<="&DATE(2025,7,31)) -> 0 | F14: =E14*AG11 -> 0 | G14: - | H14: - | J14: =COUNTIFS(General!F:F, "IP CERRADA", General!K:K, "J. FERLANTI", General!H:H, "PTE. APROBACION", General!G:G, "AUSENTE", General!O:O, ">="&DATE(2025,7,1), General!O:O, "<="&DATE(2025,7,31)) + COUNTIFS(General!F:F, "PARA FACTURAR", General!K:K, "J. FERLANTI", General!G:G, "AUSENTE", General!O:O, ">="&DATE(2025,7,1), General!O:O, "<="&DATE(2025,7,31)) -> 0 | K14: =J14*AG11 -> 0 | O14: =COUNTIFS(General!F:F, "IP CERRADA", General!K:K, "J NEIRA", General!K:K, "A MIÑO", General!H:H, "PTE. APROBACION", General!G:G, "AUSENTE", General!O:O, ">="&DATE(2025,7,1), General!O:O, "<="&DATE(2025,7,31)) -> 0 | P14: =O14*AG11 -> 0 | T14: =COUNTIFS(General!F:F, "IP CERRADA", General!K:K, "L DEL PIERO", General!K:K, "A MIÑO", General!H:H, "PTE. APROBACION", General!G:G, "AUSENTE", General!O:O, ">="&DATE(2025,7,1), General!O:O, "<="&DATE(2025,7,31)) -> 0 | U14: =T14*AG11 -> 0 | Y14: =COUNTIFS(General!F:F, "IP CERRADA", General!K:K, "E Delia", General!K:K, "E DELIA", General!H:H, "PTE. APROBACION", General!G:G, "AUSENTE", General!O:O, ">="&DATE(2025,7,1), General!O:O, "<="&DATE(2025,7,31)) -> 10 | Z14: =Y14*AG11 -> 16500 | AD14: AUSENTE | AF14: IP REMOTA | AG14: 0 | AH14: 0
E15: TOTAL | G15: TOTAL | J15: TOTAL | L15: TOTAL | O15: TOTAL | Q15: TOTAL | T15: TOTAL | V15: TOTAL | Y15: TOTAL | AA15: TOTAL | AF15: IP CAMIONES | AG15: 5625 | AH15: 5250
E16: =E4+E5+E6+E7+E9+E10+E12+E14 -> 2 | F16: =F4+F5+F6+F7+F9+F10+F12+F14 -> 11250 | G16: =G4+G5+G6+G7+G8+G9+G10+G11+G12+G13 -> 0 | H16: =H4+H5+H6+H7+H8+H9+H10+H11+H12+H13 -> 0 | J16: =J4+J5+J6+J7+J9+J10+J12+J14 -> 16 | K16: =K4+K5+K6+K7+K9+K10+K12+K14 -> 61875 | L16: =L4+L5+L6+L7+L8+L9+L10+L11+L12+L13 -> 240 | M16: =M4+M5+M6+M7+M8+M9+M10+M11+M12+M13 -> 1172250 | O16: =O4+O5+O6+O7+O8+O9+O10+O11+O12+O13+O14 -> 0 | P16: =P4+P5+P6+P7+P8+P9+P10+P11+P12+P13 -> 0 | Q16: =Q4+Q5+Q6+Q7+Q8+Q9+Q10+Q11+Q12+Q13 -> 0 | R16: =R4+R5+R6+R7+R8+R9+R10+R11+R12+R13 -> 0 | T16: =T4+T5+T6+T7+T8+T9+T10+T11+T12+T13+T14 -> 113 | U16: =U4+U5+U6+U7+U8+U9+U10+U11+U12+U13 -> 601250 | V16: =V4+V5+V6+V7+V8+V9+V10+V11+V12+V13 -> 0 | W16: =W4+W5+W6+W7+W8+W9+W10+W11+W12+W13 -> 0 | Y16: =Y4+Y5+Y6+Y7+Y8+Y9+Y10+Y11+Y12+Y13+Y14 -> 119 | Z16: =Z4+Z5+Z6+Z7+Z8+Z9+Z10+Z11+Z12+Z13 -> 597500 | AA16: =AA4+AA5+AA6+AA7+AA8+AA9+AA10+AA11+AA12+AA13 -> 0 | AB16: =AB4+AB5+AB6+AB7+AB8+AB9+AB10+AB11+AB12+AB13 -> 0 | AF16: IP VIRTUAL | AG16: - | AH16: 0
E19: LICITANDO | G19: =COUNTIFS(General!F:F, "LICITANDO REPUESTOS", General!M:M, "A MIÑO") -> 0 | J19: LICITANDO | L19: =COUNTIFS(General!F:F, "LICITANDO REPUESTOS", General!M:M, "J. FERLANTI") -> 16 | O19: LICITANDO | Q19: =COUNTIFS(General!F:F, "LICITANDO REPUESTOS", General!M:M, "J NEIRA") -> 0 | T19: LICITANDO | Y19: LICITANDO | AF19: KM RECORRIDO | AG19: 300 | AH19: -
E20: PENDIENTE | J20: PENDIENTE | L20: =COUNTIFS(General!F:F, "IP COORDINADA", General!M:M, "J. FERLANTI") -> 34 | O20: PENDIENTE | T20: PENDIENTE | Y20: PENDIENTE
E21: TOTAL HONORARIOS | G21: =E4+E5+E6+E7+E9+E10+E12+E14+G4+G5+G6+G7+G8+G9+G10+G11+G12+G13 -> 2 | H21: =F16+H16+H18 -> 11250 | J21: TOTAL HONORARIOS | L21: =J4+J5+J6+J7+J9+J10+J12+J14+L4+L5+L6+L7+L9+L8+L10+L11+L12+L13 -> 256 | M21: =M16+M18+K16 -> 1234125 | O21: TOTAL HONORARIOS | Q21: =Q4+Q5+Q6+Q7+Q8+Q9+Q10+Q11+Q12+Q13+O4+O5+O6+O8+O7+O9+O10+O11+O12+O13 -> 0 | R21: =P16+R16 -> 0 | T21: TOTAL HONORARIOS | V21: =V4+V5+V6+V7+V8+V9+V10+V11+V12+V13+T4+T5+T6+T8+T7+T9+T10+T11+T12+T13 -> 113 | W21: =U16+W16 -> 601250 | Y21: TOTAL HONORARIOS | AA21: =AA4+AA5+AA6+AA7+AA8+AA9+AA10+AA11+AA12+AA13+Y4+Y5+Y6+Y8+Y7+Y9+Y10+Y11+Y12+Y13 -> 109 | AB21: =Z16+AB16 -> 597500
S22: =
C24: TIPO DE GESTIÓN | E24: Gaston Di Clemente | J24: Franco Rodriguez | O24: Rodri Arin | T24: Cristian Cribari | Y24: Ezequiel Dzyhajlo | AD24: TIPO DE GESTIÓN
E26: PERICIAS | G26: CARGA | J26: PERICIAS | L26: CARGA | O26: PERICIAS | Q26: CARGA | T26: PERICIAS | V26: CARGA | Y26: PERICIAS | AA26: CARGA
C27: IP CON ORDEN | E27: =COUNTIFS(General!F:F, "IP CERRADA", General!K:K, "G DICLEMENTE", General!H:H, "PTE. APROBACION", General!G:G, "IP CON ORDEN", General!O:O, ">="&DATE(2025,7,1), General!O:O, "<="&DATE(2025,7,31)) -> 0 | F27: =E27*AG5 -> 0 | G27: =COUNTIFS(General!F:F, "IP CERRADA", General!M:M, "G DICLEMENTE", General!H:H, "PTE. APROBACION", General!G:G, "IP CON ORDEN", General!O:O, ">="&DATE(2025,7,1), General!O:O, "<="&DATE(2025,7,31)) -> 0 | H27: =G27*AH5 -> 0 | J27: =COUNTIFS(General!F:F, "IP CERRADA", General!K:K, "R. FRANCO", General!H:H, "PTE. APROBACION", General!G:G, "IP CON ORDEN", General!O:O, ">="&DATE(2025,7,1), General!O:O, "<="&DATE(2025,7,31)) -> 0 | K27: =J27*AG5 -> 0 | L27: =COUNTIFS(General!F:F, "IP CERRADA", General!M:M, "R. FRANCO", General!H:H, "PTE. APROBACION", General!G:G, "IP CON ORDEN", General!O:O, ">="&DATE(2025,7,1), General!O:O, "<="&DATE(2025,7,31)) -> 0 | M27: =L27*AH5 -> 0 | O27: =COUNTIFS(General!F:F, "IP CERRADA", General!K:K, "R ARIN", General!H:H, "PTE. APROBACION", General!G:G, "IP CON ORDEN", General!O:O, ">="&DATE(2025,7,1), General!O:O, "<="&DATE(2025,7,31)) -> 0 | P27: =O27*AG5 -> 0 | Q27: =COUNTIFS(General!F:F, "IP CERRADA", General!M:M, "R ARIN", General!H:H, "PTE. APROBACION", General!G:G, "IP CON ORDEN", General!O:O, ">="&DATE(2025,7,1), General!O:O, "<="&DATE(2025,7,31)) -> 0 | R27: =Q27*AH5 -> 0 | T27: =COUNTIFS(General!F:F, "IP CERRADA", General!K:K, "C. CRIBARI", General!H:H, "PTE. APROBACION", General!G:G, "IP CON ORDEN", General!O:O, ">="&DATE(2025,7,1), General!O:O, "<="&DATE(2025,7,31)) + COUNTIFS(General!F:F, "PARA FACTURAR", General!K:K, "C. CRIBARI", General!G:G, "IP CON ORDEN", General!O:O, ">="&DATE(2025,7,1), General!O:O, "<="&DATE(2025,7,31)) -> 0 | U27: =T27*AG5 -> 0 | V27: =COUNTIFS(General!F:F, "IP CERRADA", General!M:M, "C. CRIBARI", General!H:H, "PTE. APROBACION", General!G:G, "IP CON ORDEN", General!O:O, ">="&DATE(2025,7,1), General!O:O, "<="&DATE(2025,7,31)) + COUNTIFS(General!F:F, "PARA FACTURAR", General!M:M, "C. CRIBARI", General!H:H, "EN TRAMITE", General!G:G, "IP CON ORDEN") -> 0 | W27: =V27*AH5 -> 0 | Y27: =COUNTIFS(General!F:F, "IP CERRADA", General!K:K, "E DZYHAJLO", General!H:H, "PTE. APROBACION", General!G:G, "IP CON ORDEN", General!O:O, ">="&DATE(2025,7,1), General!O:O, "<="&DATE(2025,7,31)) -> 0 | Z27: =Y27*AG5 -> 0 | AB27: =AA27*AH5 -> 0 | AD27: IP CON ORDEN
C28: POSIBLE DT | E28: =COUNTIFS(General!F:F, "IP CERRADA", General!K:K, "G DICLEMENTE", General!H:H, "PTE. APROBACION", General!G:G, "POSIBLE DT", General!O:O, ">="&DATE(2025,7,1), General!O:O, "<="&DATE(2025,7,31)) -> 0 | F28: =E28*AG7 -> 0 | G28: =COUNTIFS(General!F:F, "IP CERRADA", General!M:M, "G DICLEMENTE", General!H:H, "PTE. APROBACION", General!G:G, "POSIBLE DT", General!O:O, ">="&DATE(2025,7,1), General!O:O, "<="&DATE(2025,7,31)) -> 0 | H28: =G28*AH7 -> 0 | J28: =COUNTIFS(General!F:F, "IP CERRADA", General!K:K, "R. FRANCO", General!H:H, "PTE. APROBACION", General!G:G, "POSIBLE DT", General!O:O, ">="&DATE(2025,7,1), General!O:O, "<="&DATE(2025,7,31)) -> 0 | K28: =J28*AG7 -> 0 | L28: =COUNTIFS(General!F:F, "IP CERRADA", General!M:M, "R. FRANCO", General!H:H, "PTE. APROBACION", General!G:G, "POSIBLE DT", General!O:O, ">="&DATE(2025,7,1), General!O:O, "<="&DATE(2025,7,31)) -> 0 | M28: =L28*AH7 -> 0 | O28: =COUNTIFS(General!F:F, "IP CERRADA", General!K:K, "R ARIN", General!H:H, "PTE. APROBACION", General!G:G, "POSIBLE DT", General!O:O, ">="&DATE(2025,7,1), General!O:O, "<="&DATE(2025,7,31)) -> 0 | P28: =O28*AG7 -> 0 | Q28: =COUNTIFS(General!F:F, "IP CERRADA", General!M:M, "R ARIN", General!H:H, "PTE. APROBACION", General!G:G, "POSIBLE DT", General!O:O, ">="&DATE(2025,7,1), General!O:O, "<="&DATE(2025,7,31)) -> 0 | R28: =Q28*AH7 -> 0 | T28: =COUNTIFS(General!F:F, "IP CERRADA", General!K:K, "C. CRIBARI", General!H:H, "PTE. APROBACION", General!G:G, "POSIBLE DT", General!O:O, ">="&DATE(2025,7,1), General!O:O, "<="&DATE(2025,7,31)) + COUNTIFS(General!F:F, "PARA FACTURAR", General!K:K, "C. CRIBARI", General!G:G, "POSIBLE DT", General!O:O, ">="&DATE(2025,7,1), General!O:O, "<="&DATE(2025,7,31)) -> 0 | U28: =T28*AG7 -> 0 | V28: =COUNTIFS(General!F:F, "IP CERRADA", General!M:M, "C. CRIBARI", General!H:H, "PTE. APROBACION", General!G:G, "POSIBLE DT", General!O:O, ">="&DATE(2025,7,1), General!O:O, "<="&DATE(2025,7,31)) + COUNTIFS(General!F:F, "PARA FACTURAR", General!M:M, "C. CRIBARI", General!H:H, "EN TRAMITE", General!G:G, "POSIBLE DT", General!O:O, ">="&DATE(2025,7,1), General!O:O, "<="&DATE(2025,7,31)) -> 0 | W28: =V28*AH7 -> 0 | Y28: =COUNTIFS(General!F:F, "IP CERRADA", General!K:K, "E DZYHAJLO", General!H:H, "PTE. APROBACION", General!G:G, "POSIBLE DT", General!O:O, ">="&DATE(2025,7,1), General!O:O, "<="&DATE(2025,7,31)) -> 0 | Z28: =Y28*AG7 -> 0 | AB28: =AA28*AH7 -> 0 | AD28: POSIBLE DT
